Workbook

Sheet Dynamic Spine Calculator
C3: Arrow Inputs | I3: Fletching Type or Weight (grains) | L3: Arrow Outputs
C4: Arrow Shaft Size | D4: BOP Length (inches) | E4: Point Weight (grains) | F4: Insert Weight | G4: Footing (Y/N) | H4: Nock End Weight (grains) | J4: Dynamic Spine (pounds) | L4: Total Weight (grains) | M4: Specific Weight (GPP) | N4: F.O.C. (%) | O4: Speed (FPS) | P4: Energy (ft-lbs)
C5: 1916 | D5: 30 | E5: 90 | F5: 16 | G5: No | H5: 15.5 | I5: Other | J5: =P21+(P21*9.5-L5)*2.5%+(VLOOKUP(C5,C23:I200,7)-11/32)*30 -> 54.040928 | L5: =(VLOOKUP(C5,C23:H200,6))*D5+E5+F5+VLOOKUP(I5,P23:R34,3)+H5+IF(G5="Yes",G7,0) -> 440.83448 | M5: =L5/(D13+(F13-E13)*(3+LOG(D13/(100-D13))*3)) -> 11.600907 | N5: =(D5/2-M21)/D5*100 -> 8.5349494 | O5: =200/(LOG(L5/(VLOOKUP(C13,C203:D307,2)*(D13+(F13-E13)*(3+LOG(D13/(100-D13))*3))*(VLOOKUP(H13,P51:R57,3)-0.05)),10))-20 -> 168.95483 | P5: =(L5/451080)*(O5*O5) -> 27.897368
C6: 0 | D6: ← AMO Static Spine ( 2# @ 26" ) | G6: 0 | H6: - Length (in.) | I6: 18.3
C7: 0 | D7: ← Shaft Grains per Inch (GPI) | G7: 0 | H7: - Weight (gr.) | I7: If "Other" then enter total here
C8: 0 | D8: ← Shaft Diameter (inches) (X.XX or fractional equivalent)
C10: Bow Inputs | G10: Center Cut Strike Plate Position (inches) | I10: Arrow Dynamic Spine Req. (pounds)
C11: Bow Type | D11: Rated Weight (pounds) | E11: Rated Draw (inches) | F11: Your Draw (inches) | H11: String Material Type
C13: *Generic Recurve | D13: 38 | E13: 28 | F13: 28 | G13: -0.0625 | H13: FastFlight 16 strand | I13: =VLOOKUP(C13,C203:F307,2)*(D13+(F13-E13)*(3+(LOG((D13/(241-D13)+2.4),1.138)-7.59)*3))*VLOOKUP(H13,P51:R57,3)*(1+(0.015*P13))+VLOOKUP(M22,S23:T113,2) -> 50.508 | L13: Personal Form Factor | P13: 0
C14: For specific bow models, enter strike plate thickness → (X.XX or fractional equivalent) . | G14: 0.06 | H14: (inches)
B17: Static Spine Converter | D17: Deflection (inches) | F17: AMO Static Spine (#)
B18: AMO/AMA (2# @ 26") = | D18: 0 | F18: =26/D18 -> #DIV/0!
B19: ASTM (1.94# @ 28") = | D19: 0 | F19: =26/(D19*0.825) -> #DIV/0!
C21: Arrow Data | K21: Distance from BOP to balance point (A) | M21: =((VLOOKUP(C5,C23:I200,6)*D5*D5)/2+VLOOKUP(I5,P23:R34,3)*(D5-2.5)+D5*H5)/(E5+F5+IF(G5="Yes",G7,0)+(VLOOKUP(C5,C23:I200,6)*D5)+VLOOKUP(I5,P23:R34,3)+H5) -> 12.439515 | N21: Dynamic Spine w/o mass & diameter compensation | P21: =26/(VLOOKUP(C5,C23:H200,3)*(1+(D5-29-(IF(C5="Wood Shaft",-0.9,0))-(IF(G5="Yes",G6,0)))/29*2.8)*(1+((E5+F5+(IF(G5="Yes",G7,0))+(IF(G5="Yes",(G6*(VLOOKUP(C5,C23:H200,6))),0))-125-VLOOKUP(I5,P23:R34,3)+10-H5)/125*0.4))) -> 53.711547 | S21: Weight in Grams | T21: =L5/15.432 -> 28.566257
C22: Size (XX75 or XX78) | D22: Deflection @ 28" w/1.94# | E22: Deflection @ 26" w/2.0# | F22: Static Spine | G22: Weight @ 29" | H22: GPI | I22: Shaft Diameter | L22: Strike plate position | M22: =VLOOKUP(C13,C203:F307,4) -> -0.0625 | N22: Spine compensation for diameter | P22: =(VLOOKUP(C5,C23:I200,7)-11/32)*30 -> -1.40625
C23: 1416 | D23: 1.68 | E23: =D23*0.825 -> 1.386 | F23: =26/E23 -> 18.759019 | G23: 207 | H23: =G23/29 -> 7.137931 | I23: =14/64 -> 0.21875 | P23: 2 x 3" Feathers | R23: =1.6*2 -> 3.2 | S23: -0.1875 | T23: 18
C24: 1516 | D24: 1.4 | E24: =D24*0.825 -> 1.155 | F24: =26/E24 -> 22.510823 | G24: 211 | H24: =G24/29 -> 7.2758621 | I24: =15/64 -> 0.234375 | P24: 2 x 4" Feathers | R24: =2.3*2 -> 4.6 | S24: =S23+(S25-S23)/2 -> -0.17625 | T24: 17.5
C25: 1616 | D25: 1.07 | E25: =D25*0.825 -> 0.88275 | F25: =26/E25 -> 29.453413 | G25: 242 | H25: =G25/29 -> 8.3448276 | I25: =16/64 -> 0.25 | P25: 2 x 5" Feathers | R25: =3.2*2 -> 6.4 | S25: -0.165 | T25: 17
C26: 1713 | D26: 1.03 | E26: =D26*0.825 -> 0.84975 | F26: =26/E26 -> 30.597234 | G26: 216 | H26: =G26/29 -> 7.4482759 | I26: =17/64 -> 0.265625 | P26: 3 x 3" Feathers | R26: =1.6*3 -> 4.8 | S26: =S25+(S27-S25)/2 -> -0.155 | T26: 16.5
C27: 1716 | D27: 0.88 | E27: =D27*0.825 -> 0.726 | F27: =26/E27 -> 35.812672 | G27: 262 | H27: =G27/29 -> 9.0344828 | I27: =17/64 -> 0.265625 | P27: 3 x 4" Feathers | R27: =2.3*3 -> 6.9 | S27: -0.145 | T27: 16
C28: 1813 | D28: 0.86 | E28: =D28*0.825 -> 0.7095 | F28: =26/E28 -> 36.645525 | G28: 227 | H28: =G28/29 -> 7.8275862 | I28: =18/64 -> 0.28125 | P28: 3 x 5" Feathers | R28: =3.2*3 -> 9.6 | S28: =S27+(S29-S27)/2 -> -0.135 | T28: 15.5
C29: 1816 | D29: 0.75 | E29: =D29*0.825 -> 0.61875 | F29: =26/E29 -> 42.020202 | G29: 268 | H29: =G29/29 -> 9.2413793 | I29: =18/64 -> 0.28125 | P29: 4 x 3" Feathers | R29: =1.6*4 -> 6.4 | S29: -0.125 | T29: 15
C30: 1820 | D30: 0.609 | E30: =D30*0.825 -> 0.502425 | F30: =26/E30 -> 51.749017 | G30: =29*H30 -> 353.8 | H30: 12.2 | I30: =9/32 -> 0.28125 | P30: 4 x 4" Feathers | R30: =2.3*4 -> 9.2 | S30: =S29+(S31-S29)/2 -> -0.1188 | T30: 14.5
C31: 1913 | D31: 0.725 | E31: =D31*0.825 -> 0.598125 | F31: =26/E31 -> 43.469175 | G31: 241 | H31: =G31/29 -> 8.3103448 | I31: =19/64 -> 0.296875 | P31: 4 x 5" Feathers | R31: =3.2*4 -> 12.8 | S31: -0.1126 | T31: 14
C32: 1914 | D32: 0.657 | E32: =D32*0.825 -> 0.542025 | F32: =26/E32 -> 47.968267 | G32: 268 | H32: =G32/29 -> 9.2413793 | I32: =19/64 -> 0.296875 | P32: Bare Shaft | R32: 0 | S32: =S31+(S33-S31)/2 -> -0.1067 | T32: 13.5
C33: 1916 | D33: 0.62 | E33: =D33*0.825 -> 0.5115 | F33: =26/E33 -> 50.83089 | G33: 291 | H33: =G33/29 -> 10.034483 | I33: =19/64 -> 0.296875 | P33: Generic Vanes | R33: 32 | S33: -0.1008 | T33: 13
C34: 1918 | D34: 0.55 | E34: =D34*0.825 -> 0.45375 | F34: =26/E34 -> 57.300275 | G34: =29*H34 -> 348 | H34: 12 | I34: 0.297 | P34: Other | R34: =I6 -> 18.3 | S34: =S33+(S35-S33)/2 -> -0.0945 | T34: 12.5
C35: 2013 | D35: 0.6 | E35: =D35*0.825 -> 0.495 | F35: =26/E35 -> 52.525253 | G35: 262 | H35: =G35/29 -> 9.0344828 | I35: =20/64 -> 0.3125 | P35: -0.1875 | R35: 18 | S35: -0.0882 | T35: 12
C36: 2016 | D36: 0.53 | E36: =D36*0.825 -> 0.43725 | F36: =26/E36 -> 59.46255 | G36: 305 | H36: =G36/29 -> 10.517241 | I36: =20/64 -> 0.3125 | P36: -0.125 | R36: 15 | S36: =S35+(S37-S35)/2 -> -0.0819 | T36: 11.5
C37: 2018 | D37: 0.465 | E37: =D37*0.825 -> 0.383625 | F37: =26/E37 -> 67.774519 | G37: 357 | H37: =G37/29 -> 12.310345 | I37: =20/64 -> 0.3125 | P37: -0.0625 | R37: 10 | S37: -0.0756 | T37: 11
C38: 2020 | D38: 0.426 | E38: =D38*0.825 -> 0.35145 | F38: =26/E38 -> 73.979229 | G38: 392 | H38: =G38/29 -> 13.517241 | I38: =20/64 -> 0.3125 | P38: 0 | R38: 5 | S38: =S37+(S39-S37)/2 -> -0.06905 | T38: 10.5
C39: 2113 | D39: 0.53 | E39: =D39*0.825 -> 0.43725 | F39: =26/E39 -> 59.46255 | G39: 270 | H39: =G39/29 -> 9.3103448 | I39: =21/64 -> 0.328125 | P39: 0.0625 | R39: 2 | S39: -0.0625 | T39: 10
C40: 2114 | D40: 0.5 | E40: =D40*0.825 -> 0.4125 | F40: =26/E40 -> 63.030303 | G40: 285 | H40: =G40/29 -> 9.8275862 | I40: =21/64 -> 0.328125 | P40: 0.125 | R40: -2 | S40: =S39+(S41-S39)/2 -> -0.05645 | T40: 9.5
C41: 2115 | D41: 0.46 | E41: =D41*0.825 -> 0.3795 | F41: =26/E41 -> 68.511199 | G41: 313 | H41: =G41/29 -> 10.793103 | I41: =21/64 -> 0.328125 | P41: 0.1875 | R41: -5 | S41: -0.0504 | T41: 9
C42: 2117 | D42: 0.402 | E42: =D42*0.825 -> 0.33165 | F42: =26/E42 -> 78.395899 | G42: 347 | H42: =G42/29 -> 11.965517 | I42: =21/64 -> 0.328125 | P42: 0.25 | R42: -10 | S42: =S41+(S43-S41)/2 -> -0.0441 | T42: 8.5
C43: 2213 | D43: 0.46 | E43: =D43*0.825 -> 0.3795 | F43: =26/E43 -> 68.511199 | G43: 284 | H43: =G43/29 -> 9.7931034 | I43: =22/64 -> 0.34375 | P43: =5/16 -> 0.3125 | R43: -12 | S43: -0.0378 | T43: 8
C44: 2215 | D44: 0.413 | E44: =D44*0.825 -> 0.340725 | F44: =26/E44 -> 76.307873 | G44: 312 | H44: =G44/29 -> 10.758621 | I44: =22/64 -> 0.34375 | P44: 0.375 | R44: -14 | S44: =S43+(S45-S43)/2 -> -0.0315 | T44: 7.5
C45: 2216 | D45: 0.374 | E45: =D45*0.825 -> 0.30855 | F45: =26/E45 -> 84.265111 | G45: 348 | H45: =G45/29 -> 12 | I45: =22/64 -> 0.34375 | P45: =7/16 -> 0.4375 | R45: -16 | S45: -0.0252 | T45: 7
C46: 2219 | D46: 0.336 | E46: =D46*0.825 -> 0.2772 | F46: =26/E46 -> 93.795094 | G46: 398 | H46: =G46/29 -> 13.724138 | I46: =22/64 -> 0.34375 | P46: 0.5 | R46: -18 | S46: =S45+(S47-S45)/2 -> -0.0189 | T46: 6.5
C47: 2312 | D47: 0.425 | E47: =D47*0.825 -> 0.350625 | F47: =26/E47 -> 74.153298 | G47: 277 | H47: =G47/29 -> 9.5517241 | I47: =23/64 -> 0.359375 | P47: =9/16 -> 0.5625 | R47: -20 | S47: -0.0126 | T47: 6
...

Sheet Data Library
A1: Arrow Details | V1: Bow Details | AE1: 2 x 3" Feathers | AF1: =1.6*2 -> 3.2
F2: AMO Deflection | G2: AMO Static Spine | H2: Physical Detail | P2: Dynamic Spine | S2: Fletching | W2: Weight @ Rated Draw | X2: String Material & Strand Count | Y2: Bow Center Cut | Z2: Strike Plate Thickness | AA2: Strike Position Faction - OR - Decimal | AC2: Brace Height | AD2: Dynamic Spine Req. | AE2: 2 x 4" Feathers | AF2: =2.3*2 -> 4.6
A3: # | B3: Date | C3: Make / Type | D3: Dia. | E3: Material | G3: Static Spine | H3: Length | I3: Footing | J3: Point | K3: Insert | L3: Nock | M3: FOC % | N3: Shaft GPI | O3: Total Wt. | Q3: Crown | R3: Crest | S3: Type | T3: Wing | U3: Color (hen / cock) | V3: Make / Type | AE3: 2 x 5" Feathers | AF3: =3.2*2 -> 6.4
A4: Select HERE to read note. | C4: ='Dynamic Spine Calculator'!C5 -> 1916 | D4: =VLOOKUP(C4,'Dynamic Spine Calculator'!C23:I200,7,FALSE) -> 0.296875 | F4: =VLOOKUP(C4,'Dynamic Spine Calculator'!C23:I200,3,FALSE) -> 0.5115 | G4: =VLOOKUP(C4,'Dynamic Spine Calculator'!C23:I200,4,FALSE) -> 50.83089 | H4: ='Dynamic Spine Calculator'!D5 -> 30 | I4: ='Dynamic Spine Calculator'!G5 -> No | J4: ='Dynamic Spine Calculator'!E5 -> 90 | K4: ='Dynamic Spine Calculator'!F5 -> 16 | L4: ='Dynamic Spine Calculator'!H5 -> 15.5 | M4: ='Dynamic Spine Calculator'!N5 -> 8.5349494 | N4: =VLOOKUP('Data Library'!C4,'Dynamic Spine Calculator'!C23:I200,6,FALSE) -> 10.034483 | O4: ='Dynamic Spine Calculator'!L5 -> 440.83448 | P4: ='Dynamic Spine Calculator'!J5 -> 54.040928 | S4: ='Dynamic Spine Calculator'!I5 -> Other | V4: ='Dynamic Spine Calculator'!C13 -> *Generic Recurve | W4: ='Dynamic Spine Calculator'!D13 -> 38 | X4: ='Dynamic Spine Calculator'!H13 -> FastFlight 16 strand | Y4: =VLOOKUP(V4,'Dynamic Spine Calculator'!C203:F307,3,FALSE) -> N/A | Z4: =IF(Y4="N/A","N/A",AB4-Y4) -> N/A | AA4: =VLOOKUP(V4,'Dynamic Spine Calculator'!C203:F307,4,FALSE) -> -0.0625 | AB4: =VLOOKUP(V4,'Dynamic Spine Calculator'!C203:F307,4,FALSE) -> -0.0625 | AD4: ='Dynamic Spine Calculator'!I13 -> 50.508 | AE4: 3 x 3" Feathers | AF4: =1.6*3 -> 4.8
A5: 1 | B5: 42688 | C5: 1916 | D5: 0.296875 | F5: 0.5115 | G5: 50.83089 | H5: 30 | I5: No | J5: 75 | K5: 0 | L5: 15.5 | M5: 3.876111 | N5: 10.034483 | O5: 423.53448 | P5: 67.678412 | S5: Generic Vanes | V5: *Generic Recurve | W5: 28 | X5: FastFlight 16 strand | Y5: N/A | Z5: N/A | AA5: -0.125 | AB5: -0.125 | AD5: 44.848 | AE5: 3 x 4" Feathers | AF5: =2.3*3 -> 6.9
A6: 2 | B6: 42688 | C6: Easton Carbon One 660 | D6: 0.23 | F6: 0.5445 | G6: 47.75023 | H6: 30 | I6: No | J6: 100 | K6: 0 | L6: 15.5 | M6: 8.3695128 | N6: 6.6 | O6: 345.5 | P6: 55.30992 | S6: Generic Vanes | V6: *Generic Recurve | W6: 36 | X6: FastFlight 16 strand | Y6: N/A | Z6: N/A | AA6: -0.125 | AB6: -0.125 | AD6: 53.376 | AE6: 3 x 5" Feathers | AF6: =3.2*3 -> 9.6
A7: 3 | AE7: 4 x 3" Feathers | AF7: =1.6*4 -> 6.4
A8: 4 | AE8: 4 x 4" Feathers | AF8: =2.3*4 -> 9.2
A9: 5 | AE9: 4 x 5" Feathers | AF9: =3.2*4 -> 12.8
A10: 6 | AE10: Bare Shaft | AF10: 0
A11: 7 | AE11: Generic Vanes | AF11: 32
A12: 8
A13: 9
A14: 10
A15: 11
A16: 12
A17: 13
A18: 14
A19: 15
A20: 16
A21: 17
A22: 18
A23: 19
... A106: 100
